Traceback (most recent call last):
  File "/home/chsu/mambaforge/envs/cefibook/lib/python3.10/site-packages/jupyter_cache/executors/utils.py", line 58, in single_nb_execution
    executenb(
  File "/home/chsu/mambaforge/envs/cefibook/lib/python3.10/site-packages/nbclient/client.py", line 1305, in execute
    return NotebookClient(nb=nb, resources=resources, km=km, **kwargs).execute()
  File "/home/chsu/mambaforge/envs/cefibook/lib/python3.10/site-packages/jupyter_core/utils/__init__.py", line 166, in wrapped
    return loop.run_until_complete(inner)
  File "/home/chsu/mambaforge/envs/cefibook/lib/python3.10/asyncio/base_events.py", line 649, in run_until_complete
    return future.result()
  File "/home/chsu/mambaforge/envs/cefibook/lib/python3.10/site-packages/nbclient/client.py", line 705, in async_execute
    await self.async_execute_cell(
  File "/home/chsu/mambaforge/envs/cefibook/lib/python3.10/site-packages/nbclient/client.py", line 1058, in async_execute_cell
    await self._check_raise_for_error(cell, cell_index, exec_reply)
  File "/home/chsu/mambaforge/envs/cefibook/lib/python3.10/site-packages/nbclient/client.py", line 914, in _check_raise_for_error
    raise CellExecutionError.from_cell_and_msg(cell, exec_reply_content)
nbclient.exceptions.CellExecutionError: An error occurred while executing the following cell:
------------------
import numpy as np
cruises = np.unique(ds.cruise.data)
------------------


[0;31m---------------------------------------------------------------------------[0m
[0;31mAttributeError[0m                            Traceback (most recent call last)
Cell [0;32mIn[6], line 2[0m
[1;32m      1[0m [38;5;28;01mimport[39;00m [38;5;21;01mnumpy[39;00m [38;5;28;01mas[39;00m [38;5;21;01mnp[39;00m
[0;32m----> 2[0m cruises [38;5;241m=[39m np[38;5;241m.[39munique([43mds[49m[38;5;241;43m.[39;49m[43mcruise[49m[38;5;241m.[39mdata)

File [0;32m~/mambaforge/envs/cefibook/lib/python3.10/site-packages/xarray/core/common.py:278[0m, in [0;36mAttrAccessMixin.__getattr__[0;34m(self, name)[0m
[1;32m    276[0m         [38;5;28;01mwith[39;00m suppress([38;5;167;01mKeyError[39;00m):
[1;32m    277[0m             [38;5;28;01mreturn[39;00m source[name]
[0;32m--> 278[0m [38;5;28;01mraise[39;00m [38;5;167;01mAttributeError[39;00m(
[1;32m    279[0m     [38;5;124mf[39m[38;5;124m"[39m[38;5;132;01m{[39;00m[38;5;28mtype[39m([38;5;28mself[39m)[38;5;241m.[39m[38;5;18m__name__[39m[38;5;132;01m!r}[39;00m[38;5;124m object has no attribute [39m[38;5;132;01m{[39;00mname[38;5;132;01m!r}[39;00m[38;5;124m"[39m
[1;32m    280[0m )

[0;31mAttributeError[0m: 'Dataset' object has no attribute 'cruise'

